Traceback (most recent call last):
  File "/opt/anaconda3/lib/python3.9/site-packages/jupyter_cache/executors/utils.py", line 51, in single_nb_execution
    executenb(
  File "/opt/anaconda3/lib/python3.9/site-packages/nbclient/client.py", line 1112, in execute
    return NotebookClient(nb=nb, resources=resources, km=km, **kwargs).execute()
  File "/opt/anaconda3/lib/python3.9/site-packages/nbclient/util.py", line 74, in wrapped
    return just_run(coro(*args, **kwargs))
  File "/opt/anaconda3/lib/python3.9/site-packages/nbclient/util.py", line 53, in just_run
    return loop.run_until_complete(coro)
  File "/opt/anaconda3/lib/python3.9/asyncio/base_events.py", line 642, in run_until_complete
    return future.result()
  File "/opt/anaconda3/lib/python3.9/site-packages/nbclient/client.py", line 553, in async_execute
    await self.async_execute_cell(
  File "/opt/anaconda3/lib/python3.9/site-packages/nbclient/client.py", line 857, in async_execute_cell
    self._check_raise_for_error(cell, exec_reply)
  File "/opt/anaconda3/lib/python3.9/site-packages/nbclient/client.py", line 760, in _check_raise_for_error
    raise CellExecutionError.from_cell_and_msg(cell, exec_reply_content)
nbclient.exceptions.CellExecutionError: An error occurred while executing the following cell:
------------------
sp.zeta(1j)
------------------

[0;31m---------------------------------------------------------------------------[0m
[0;31mTypeError[0m                                 Traceback (most recent call last)
[0;32m/var/folders/vh/rcz751b57355h3qzj37sc3080000gp/T/ipykernel_753/817459801.py[0m in [0;36m<module>[0;34m[0m
[0;32m----> 1[0;31m [0msp[0m[0;34m.[0m[0mzeta[0m[0;34m([0m[0;36m1j[0m[0;34m)[0m[0;34m[0m[0;34m[0m[0m
[0m
[0;32m/opt/anaconda3/lib/python3.9/site-packages/scipy/special/_basic.py[0m in [0;36mzeta[0;34m(x, q, out)[0m
[1;32m   2570[0m     """
[1;32m   2571[0m     [0;32mif[0m [0mq[0m [0;32mis[0m [0;32mNone[0m[0;34m:[0m[0;34m[0m[0;34m[0m[0m
[0;32m-> 2572[0;31m         [0;32mreturn[0m [0mufuncs[0m[0;34m.[0m[0m_riemann_zeta[0m[0;34m([0m[0mx[0m[0;34m,[0m [0mout[0m[0;34m)[0m[0;34m[0m[0;34m[0m[0m
[0m[1;32m   2573[0m     [0;32melse[0m[0;34m:[0m[0;34m[0m[0;34m[0m[0m
[1;32m   2574[0m         [0;32mreturn[0m [0mufuncs[0m[0;34m.[0m[0m_zeta[0m[0;34m([0m[0mx[0m[0;34m,[0m [0mq[0m[0;34m,[0m [0mout[0m[0;34m)[0m[0;34m[0m[0;34m[0m[0m

[0;31mTypeError[0m: ufunc '_riemann_zeta' not supported for the input types, and the inputs could not be safely coerced to any supported types according to the casting rule ''safe''
TypeError: ufunc '_riemann_zeta' not supported for the input types, and the inputs could not be safely coerced to any supported types according to the casting rule ''safe''

